[2023-09-28T22:23:58.626+0000] {taskinstance.py:1165} INFO - Dependencies all met for <TaskInstance: process_data.get_data scheduled__2023-09-27T00:00:00+00:00 [queued]>
[2023-09-28T22:23:58.654+0000] {taskinstance.py:1165} INFO - Dependencies all met for <TaskInstance: process_data.get_data scheduled__2023-09-27T00:00:00+00:00 [queued]>
[2023-09-28T22:23:58.655+0000] {taskinstance.py:1362} INFO - 
--------------------------------------------------------------------------------
[2023-09-28T22:23:58.657+0000] {taskinstance.py:1363} INFO - Starting attempt 1 of 1
[2023-09-28T22:23:58.657+0000] {taskinstance.py:1364} INFO - 
--------------------------------------------------------------------------------
[2023-09-28T22:23:58.686+0000] {taskinstance.py:1383} INFO - Executing <Task(_PythonDecoratedOperator): get_data> on 2023-09-27 00:00:00+00:00
[2023-09-28T22:23:58.697+0000] {standard_task_runner.py:55} INFO - Started process 81 to run task
[2023-09-28T22:23:58.706+0000] {standard_task_runner.py:82} INFO - Running: ['***', 'tasks', 'run', 'process_data', 'get_data', 'scheduled__2023-09-27T00:00:00+00:00', '--job-id', '103', '--raw', '--subdir', 'DAGS_FOLDER/data_retrieval.py', '--cfg-path', '/tmp/tmpi3dpq4ip']
[2023-09-28T22:23:58.707+0000] {standard_task_runner.py:83} INFO - Job 103: Subtask get_data
[2023-09-28T22:23:58.844+0000] {task_command.py:376} INFO - Running <TaskInstance: process_data.get_data scheduled__2023-09-27T00:00:00+00:00 [running]> on host 35dd594c6205
[2023-09-28T22:23:59.012+0000] {taskinstance.py:1592} INFO - Exporting the following env vars:
AIRFLOW_CTX_DAG_OWNER=***
AIRFLOW_CTX_DAG_ID=process_data
AIRFLOW_CTX_TASK_ID=get_data
AIRFLOW_CTX_EXECUTION_DATE=2023-09-27T00:00:00+00:00
AIRFLOW_CTX_TRY_NUMBER=1
AIRFLOW_CTX_DAG_RUN_ID=scheduled__2023-09-27T00:00:00+00:00
[2023-09-28T22:23:59.033+0000] {base.py:71} INFO - Using connection ID 'pgdatabase' for task execution.
[2023-09-28T22:24:09.041+0000] {taskinstance.py:1851} ERROR - Task failed with exception
Traceback (most recent call last):
  File "/home/airflow/.local/lib/python3.7/site-packages/airflow/decorators/base.py", line 188, in execute
    return_value = super().execute(context)
  File "/home/airflow/.local/lib/python3.7/site-packages/airflow/operators/python.py", line 175, in execute
    return_value = self.execute_callable()
  File "/home/airflow/.local/lib/python3.7/site-packages/airflow/operators/python.py", line 193, in execute_callable
    return self.python_callable(*self.op_args, **self.op_kwargs)
  File "/opt/airflow/dags/data_retrieval.py", line 18, in get_data
    conn = postgres_hook.get_conn()
  File "/home/airflow/.local/lib/python3.7/site-packages/airflow/providers/postgres/hooks/postgres.py", line 115, in get_conn
    self.conn = psycopg2.connect(**conn_args)
  File "/home/airflow/.local/lib/python3.7/site-packages/psycopg2/__init__.py", line 122, in connect
    conn = _connect(dsn, connection_factory=connection_factory, **kwasync)
psycopg2.OperationalError: could not translate host name "pgdatabase" to address: Temporary failure in name resolution

[2023-09-28T22:24:09.051+0000] {taskinstance.py:1406} INFO - Marking task as FAILED. dag_id=process_data, task_id=get_data, execution_date=20230927T000000, start_date=20230928T222358, end_date=20230928T222409
[2023-09-28T22:24:09.062+0000] {standard_task_runner.py:105} ERROR - Failed to execute job 103 for task get_data (could not translate host name "pgdatabase" to address: Temporary failure in name resolution
; 81)
[2023-09-28T22:24:09.082+0000] {local_task_job.py:164} INFO - Task exited with return code 1
[2023-09-28T22:24:09.097+0000] {local_task_job.py:273} INFO - 0 downstream tasks scheduled from follow-on schedule check
