[2023-09-23T00:27:56.148+0000] {taskinstance.py:1165} INFO - Dependencies all met for <TaskInstance: extract_data.transfer_database manual__2023-09-23T00:27:54.862083+00:00 [queued]>
[2023-09-23T00:27:56.160+0000] {taskinstance.py:1165} INFO - Dependencies all met for <TaskInstance: extract_data.transfer_database manual__2023-09-23T00:27:54.862083+00:00 [queued]>
[2023-09-23T00:27:56.161+0000] {taskinstance.py:1362} INFO - 
--------------------------------------------------------------------------------
[2023-09-23T00:27:56.162+0000] {taskinstance.py:1363} INFO - Starting attempt 1 of 1
[2023-09-23T00:27:56.162+0000] {taskinstance.py:1364} INFO - 
--------------------------------------------------------------------------------
[2023-09-23T00:27:56.178+0000] {taskinstance.py:1383} INFO - Executing <Task(GenericTransfer): transfer_database> on 2023-09-23 00:27:54.862083+00:00
[2023-09-23T00:27:56.182+0000] {standard_task_runner.py:55} INFO - Started process 1313 to run task
[2023-09-23T00:27:56.185+0000] {standard_task_runner.py:82} INFO - Running: ['***', 'tasks', 'run', 'extract_data', 'transfer_database', 'manual__2023-09-23T00:27:54.862083+00:00', '--job-id', '63', '--raw', '--subdir', 'DAGS_FOLDER/transfer_data.py', '--cfg-path', '/tmp/tmp7f1yxly7']
[2023-09-23T00:27:56.186+0000] {standard_task_runner.py:83} INFO - Job 63: Subtask transfer_database
[2023-09-23T00:27:56.239+0000] {task_command.py:376} INFO - Running <TaskInstance: extract_data.transfer_database manual__2023-09-23T00:27:54.862083+00:00 [running]> on host c71b9a166a04
[2023-09-23T00:27:56.300+0000] {taskinstance.py:1592} INFO - Exporting the following env vars:
AIRFLOW_CTX_DAG_OWNER=***
AIRFLOW_CTX_DAG_ID=extract_data
AIRFLOW_CTX_TASK_ID=transfer_database
AIRFLOW_CTX_EXECUTION_DATE=2023-09-23T00:27:54.862083+00:00
AIRFLOW_CTX_TRY_NUMBER=1
AIRFLOW_CTX_DAG_RUN_ID=manual__2023-09-23T00:27:54.862083+00:00
[2023-09-23T00:27:56.308+0000] {base.py:71} INFO - Using connection ID 'pgdatabase' for task execution.
[2023-09-23T00:27:56.490+0000] {base.py:71} INFO - Using connection ID 'postgres' for task execution.
[2023-09-23T00:27:56.647+0000] {generic_transfer.py:76} INFO - Extracting data from pgdatabase
[2023-09-23T00:27:56.647+0000] {generic_transfer.py:77} INFO - Executing: 
 SELECT * FROM machine_learning_customerchurn;
[2023-09-23T00:27:56.653+0000] {base.py:71} INFO - Using connection ID 'pgdatabase' for task execution.
[2023-09-23T00:27:56.660+0000] {generic_transfer.py:104} INFO - Inserting rows into postgres
[2023-09-23T00:27:56.666+0000] {base.py:71} INFO - Using connection ID 'postgres' for task execution.
[2023-09-23T00:27:56.670+0000] {taskinstance.py:1851} ERROR - Task failed with exception
Traceback (most recent call last):
  File "/home/airflow/.local/lib/python3.7/site-packages/airflow/operators/generic_transfer.py", line 105, in execute
    insert_rows(table=self.destination_table, rows=results, **self.insert_args)
  File "/home/airflow/.local/lib/python3.7/site-packages/airflow/providers/common/sql/hooks/sql.py", line 409, in insert_rows
    cur.execute(sql, values)
psycopg2.errors.UndefinedTable: relation "machine_learing_customerchurn" does not exist
LINE 1: INSERT INTO machine_learing_customerchurn  VALUES (1,'MT',73...
                    ^

[2023-09-23T00:27:56.677+0000] {taskinstance.py:1406} INFO - Marking task as FAILED. dag_id=extract_data, task_id=transfer_database, execution_date=20230923T002754, start_date=20230923T002756, end_date=20230923T002756
[2023-09-23T00:27:56.686+0000] {standard_task_runner.py:105} ERROR - Failed to execute job 63 for task transfer_database (relation "machine_learing_customerchurn" does not exist
LINE 1: INSERT INTO machine_learing_customerchurn  VALUES (1,'MT',73...
                    ^
; 1313)
[2023-09-23T00:27:56.720+0000] {local_task_job.py:164} INFO - Task exited with return code 1
[2023-09-23T00:27:56.737+0000] {local_task_job.py:273} INFO - 0 downstream tasks scheduled from follow-on schedule check
