[2023-09-28T22:23:58.561+0000] {taskinstance.py:1165} INFO - Dependencies all met for <TaskInstance: extract_data.transfer_database scheduled__2023-09-27T00:00:00+00:00 [queued]>
[2023-09-28T22:23:58.583+0000] {taskinstance.py:1165} INFO - Dependencies all met for <TaskInstance: extract_data.transfer_database scheduled__2023-09-27T00:00:00+00:00 [queued]>
[2023-09-28T22:23:58.583+0000] {taskinstance.py:1362} INFO - 
--------------------------------------------------------------------------------
[2023-09-28T22:23:58.585+0000] {taskinstance.py:1363} INFO - Starting attempt 1 of 1
[2023-09-28T22:23:58.585+0000] {taskinstance.py:1364} INFO - 
--------------------------------------------------------------------------------
[2023-09-28T22:23:58.625+0000] {taskinstance.py:1383} INFO - Executing <Task(GenericTransfer): transfer_database> on 2023-09-27 00:00:00+00:00
[2023-09-28T22:23:58.632+0000] {standard_task_runner.py:55} INFO - Started process 78 to run task
[2023-09-28T22:23:58.640+0000] {standard_task_runner.py:82} INFO - Running: ['***', 'tasks', 'run', 'extract_data', 'transfer_database', 'scheduled__2023-09-27T00:00:00+00:00', '--job-id', '101', '--raw', '--subdir', 'DAGS_FOLDER/transfer_data.py', '--cfg-path', '/tmp/tmpsj99wgfx']
[2023-09-28T22:23:58.641+0000] {standard_task_runner.py:83} INFO - Job 101: Subtask transfer_database
[2023-09-28T22:23:58.788+0000] {task_command.py:376} INFO - Running <TaskInstance: extract_data.transfer_database scheduled__2023-09-27T00:00:00+00:00 [running]> on host 35dd594c6205
[2023-09-28T22:23:58.941+0000] {taskinstance.py:1592} INFO - Exporting the following env vars:
AIRFLOW_CTX_DAG_OWNER=***
AIRFLOW_CTX_DAG_ID=extract_data
AIRFLOW_CTX_TASK_ID=transfer_database
AIRFLOW_CTX_EXECUTION_DATE=2023-09-27T00:00:00+00:00
AIRFLOW_CTX_TRY_NUMBER=1
AIRFLOW_CTX_DAG_RUN_ID=scheduled__2023-09-27T00:00:00+00:00
[2023-09-28T22:23:58.966+0000] {base.py:71} INFO - Using connection ID 'pgdatabase' for task execution.
[2023-09-28T22:23:59.521+0000] {base.py:71} INFO - Using connection ID 'postgres' for task execution.
[2023-09-28T22:23:59.772+0000] {generic_transfer.py:76} INFO - Extracting data from pgdatabase
[2023-09-28T22:23:59.773+0000] {generic_transfer.py:77} INFO - Executing: 
 SELECT state,account_length,area_code,phone_number,international_plan,voice_mail_plan,number_vmail_messages,total_day_minutes,total_day_calls,total_day_charge,total_eve_minutes,total_eve_calls,total_eve_charge,total_night_minutes,total_night_calls,total_night_charge,total_intl_minutes,total_intl_calls,total_intl_charge,customer_service_calls,churn FROM public.machine_learning_customerchurn WHERE customer_service_calls > 2;
[2023-09-28T22:23:59.783+0000] {base.py:71} INFO - Using connection ID 'pgdatabase' for task execution.
[2023-09-28T22:24:09.792+0000] {taskinstance.py:1851} ERROR - Task failed with exception
Traceback (most recent call last):
  File "/home/airflow/.local/lib/python3.7/site-packages/airflow/operators/generic_transfer.py", line 85, in execute
    results = get_records(self.sql)
  File "/home/airflow/.local/lib/python3.7/site-packages/airflow/providers/common/sql/hooks/sql.py", line 212, in get_records
    with closing(self.get_conn()) as conn:
  File "/home/airflow/.local/lib/python3.7/site-packages/airflow/providers/postgres/hooks/postgres.py", line 115, in get_conn
    self.conn = psycopg2.connect(**conn_args)
  File "/home/airflow/.local/lib/python3.7/site-packages/psycopg2/__init__.py", line 122, in connect
    conn = _connect(dsn, connection_factory=connection_factory, **kwasync)
psycopg2.OperationalError: could not translate host name "pgdatabase" to address: Temporary failure in name resolution

[2023-09-28T22:24:09.808+0000] {taskinstance.py:1406} INFO - Marking task as FAILED. dag_id=extract_data, task_id=transfer_database, execution_date=20230927T000000, start_date=20230928T222358, end_date=20230928T222409
[2023-09-28T22:24:09.820+0000] {standard_task_runner.py:105} ERROR - Failed to execute job 101 for task transfer_database (could not translate host name "pgdatabase" to address: Temporary failure in name resolution
; 78)
[2023-09-28T22:24:09.855+0000] {local_task_job.py:164} INFO - Task exited with return code 1
[2023-09-28T22:24:09.870+0000] {local_task_job.py:273} INFO - 0 downstream tasks scheduled from follow-on schedule check
