[2023-09-23T12:02:47.522+0000] {taskinstance.py:1165} INFO - Dependencies all met for <TaskInstance: extract_data.transfer_database manual__2023-09-23T12:02:47.001906+00:00 [queued]>
[2023-09-23T12:02:47.532+0000] {taskinstance.py:1165} INFO - Dependencies all met for <TaskInstance: extract_data.transfer_database manual__2023-09-23T12:02:47.001906+00:00 [queued]>
[2023-09-23T12:02:47.533+0000] {taskinstance.py:1362} INFO - 
--------------------------------------------------------------------------------
[2023-09-23T12:02:47.534+0000] {taskinstance.py:1363} INFO - Starting attempt 1 of 1
[2023-09-23T12:02:47.534+0000] {taskinstance.py:1364} INFO - 
--------------------------------------------------------------------------------
[2023-09-23T12:02:47.548+0000] {taskinstance.py:1383} INFO - Executing <Task(GenericTransfer): transfer_database> on 2023-09-23 12:02:47.001906+00:00
[2023-09-23T12:02:47.553+0000] {standard_task_runner.py:55} INFO - Started process 4522 to run task
[2023-09-23T12:02:47.555+0000] {standard_task_runner.py:82} INFO - Running: ['***', 'tasks', 'run', 'extract_data', 'transfer_database', 'manual__2023-09-23T12:02:47.001906+00:00', '--job-id', '81', '--raw', '--subdir', 'DAGS_FOLDER/transfer_data.py', '--cfg-path', '/tmp/tmpvl548g9d']
[2023-09-23T12:02:47.556+0000] {standard_task_runner.py:83} INFO - Job 81: Subtask transfer_database
[2023-09-23T12:02:47.611+0000] {task_command.py:376} INFO - Running <TaskInstance: extract_data.transfer_database manual__2023-09-23T12:02:47.001906+00:00 [running]> on host 20e0c20d2e1d
[2023-09-23T12:02:47.679+0000] {taskinstance.py:1592} INFO - Exporting the following env vars:
AIRFLOW_CTX_DAG_OWNER=***
AIRFLOW_CTX_DAG_ID=extract_data
AIRFLOW_CTX_TASK_ID=transfer_database
AIRFLOW_CTX_EXECUTION_DATE=2023-09-23T12:02:47.001906+00:00
AIRFLOW_CTX_TRY_NUMBER=1
AIRFLOW_CTX_DAG_RUN_ID=manual__2023-09-23T12:02:47.001906+00:00
[2023-09-23T12:02:47.689+0000] {base.py:71} INFO - Using connection ID 'pgdatabase' for task execution.
[2023-09-23T12:02:47.853+0000] {base.py:71} INFO - Using connection ID 'postgres' for task execution.
[2023-09-23T12:02:47.991+0000] {generic_transfer.py:76} INFO - Extracting data from pgdatabase
[2023-09-23T12:02:47.992+0000] {generic_transfer.py:77} INFO - Executing: 
 SELECT state,account_length,area_code,phone_number,international_plan,voice_mail_plan,number_vmail_messages,total_day_minutes,total_day_calls,total_day_charge,total_eve_minutes,total_eve_calls,total_eve_charge,total_night_minutes,total_night_calls,total_night_charge,total_intl_minutes,total_intl_calls,total_intl_charge,customer_service_calls,churn FROM public.machine_learning_customerchurn WHERE customer_service_calls >2;
[2023-09-23T12:02:47.998+0000] {base.py:71} INFO - Using connection ID 'pgdatabase' for task execution.
[2023-09-23T12:02:48.007+0000] {generic_transfer.py:104} INFO - Inserting rows into postgres
[2023-09-23T12:02:48.014+0000] {base.py:71} INFO - Using connection ID 'postgres' for task execution.
[2023-09-23T12:02:48.019+0000] {taskinstance.py:1851} ERROR - Task failed with exception
Traceback (most recent call last):
  File "/home/airflow/.local/lib/python3.7/site-packages/airflow/operators/generic_transfer.py", line 105, in execute
    insert_rows(table=self.destination_table, rows=results, **self.insert_args)
  File "/home/airflow/.local/lib/python3.7/site-packages/airflow/providers/common/sql/hooks/sql.py", line 409, in insert_rows
    cur.execute(sql, values)
psycopg2.errors.UndefinedTable: relation "public.machine_learing_customerchurn" does not exist
LINE 1: INSERT INTO public.machine_learing_customerchurn  VALUES ('O...
                    ^

[2023-09-23T12:02:48.027+0000] {taskinstance.py:1406} INFO - Marking task as FAILED. dag_id=extract_data, task_id=transfer_database, execution_date=20230923T120247, start_date=20230923T120247, end_date=20230923T120248
[2023-09-23T12:02:48.083+0000] {standard_task_runner.py:105} ERROR - Failed to execute job 81 for task transfer_database (relation "public.machine_learing_customerchurn" does not exist
LINE 1: INSERT INTO public.machine_learing_customerchurn  VALUES ('O...
                    ^
; 4522)
[2023-09-23T12:02:48.131+0000] {local_task_job.py:164} INFO - Task exited with return code 1
[2023-09-23T12:02:48.150+0000] {local_task_job.py:273} INFO - 0 downstream tasks scheduled from follow-on schedule check
