[2023-09-23T00:29:39.717+0000] {taskinstance.py:1165} INFO - Dependencies all met for <TaskInstance: extract_data.transfer_database manual__2023-09-23T00:29:38.829212+00:00 [queued]>
[2023-09-23T00:29:39.730+0000] {taskinstance.py:1165} INFO - Dependencies all met for <TaskInstance: extract_data.transfer_database manual__2023-09-23T00:29:38.829212+00:00 [queued]>
[2023-09-23T00:29:39.731+0000] {taskinstance.py:1362} INFO - 
--------------------------------------------------------------------------------
[2023-09-23T00:29:39.732+0000] {taskinstance.py:1363} INFO - Starting attempt 1 of 1
[2023-09-23T00:29:39.733+0000] {taskinstance.py:1364} INFO - 
--------------------------------------------------------------------------------
[2023-09-23T00:29:39.747+0000] {taskinstance.py:1383} INFO - Executing <Task(GenericTransfer): transfer_database> on 2023-09-23 00:29:38.829212+00:00
[2023-09-23T00:29:39.752+0000] {standard_task_runner.py:55} INFO - Started process 1397 to run task
[2023-09-23T00:29:39.754+0000] {standard_task_runner.py:82} INFO - Running: ['***', 'tasks', 'run', 'extract_data', 'transfer_database', 'manual__2023-09-23T00:29:38.829212+00:00', '--job-id', '64', '--raw', '--subdir', 'DAGS_FOLDER/transfer_data.py', '--cfg-path', '/tmp/tmpq9y4wjl7']
[2023-09-23T00:29:39.755+0000] {standard_task_runner.py:83} INFO - Job 64: Subtask transfer_database
[2023-09-23T00:29:39.809+0000] {task_command.py:376} INFO - Running <TaskInstance: extract_data.transfer_database manual__2023-09-23T00:29:38.829212+00:00 [running]> on host c71b9a166a04
[2023-09-23T00:29:39.869+0000] {taskinstance.py:1592} INFO - Exporting the following env vars:
AIRFLOW_CTX_DAG_OWNER=***
AIRFLOW_CTX_DAG_ID=extract_data
AIRFLOW_CTX_TASK_ID=transfer_database
AIRFLOW_CTX_EXECUTION_DATE=2023-09-23T00:29:38.829212+00:00
AIRFLOW_CTX_TRY_NUMBER=1
AIRFLOW_CTX_DAG_RUN_ID=manual__2023-09-23T00:29:38.829212+00:00
[2023-09-23T00:29:39.877+0000] {base.py:71} INFO - Using connection ID 'pgdatabase' for task execution.
[2023-09-23T00:29:40.102+0000] {base.py:71} INFO - Using connection ID 'postgres' for task execution.
[2023-09-23T00:29:40.260+0000] {generic_transfer.py:76} INFO - Extracting data from pgdatabase
[2023-09-23T00:29:40.261+0000] {generic_transfer.py:77} INFO - Executing: 
 SELECT * FROM machine_learning_customerchurn;
[2023-09-23T00:29:40.267+0000] {base.py:71} INFO - Using connection ID 'pgdatabase' for task execution.
[2023-09-23T00:29:40.273+0000] {generic_transfer.py:104} INFO - Inserting rows into postgres
[2023-09-23T00:29:40.280+0000] {base.py:71} INFO - Using connection ID 'postgres' for task execution.
[2023-09-23T00:29:40.285+0000] {taskinstance.py:1851} ERROR - Task failed with exception
Traceback (most recent call last):
  File "/home/airflow/.local/lib/python3.7/site-packages/airflow/operators/generic_transfer.py", line 105, in execute
    insert_rows(table=self.destination_table, rows=results, **self.insert_args)
  File "/home/airflow/.local/lib/python3.7/site-packages/airflow/providers/common/sql/hooks/sql.py", line 409, in insert_rows
    cur.execute(sql, values)
psycopg2.errors.UndefinedTable: relation "machine_learing_customerchurn" does not exist
LINE 1: INSERT INTO machine_learing_customerchurn  VALUES (1,'MT',73...
                    ^

[2023-09-23T00:29:40.292+0000] {taskinstance.py:1406} INFO - Marking task as FAILED. dag_id=extract_data, task_id=transfer_database, execution_date=20230923T002938, start_date=20230923T002939, end_date=20230923T002940
[2023-09-23T00:29:40.303+0000] {standard_task_runner.py:105} ERROR - Failed to execute job 64 for task transfer_database (relation "machine_learing_customerchurn" does not exist
LINE 1: INSERT INTO machine_learing_customerchurn  VALUES (1,'MT',73...
                    ^
; 1397)
[2023-09-23T00:29:40.329+0000] {local_task_job.py:164} INFO - Task exited with return code 1
[2023-09-23T00:29:40.346+0000] {local_task_job.py:273} INFO - 0 downstream tasks scheduled from follow-on schedule check
