[2023-09-21T13:37:38.550+0000] {taskinstance.py:1165} INFO - Dependencies all met for <TaskInstance: generic_transfer_operator.load_upload_data manual__2023-09-21T13:37:36.894582+00:00 [queued]>
[2023-09-21T13:37:38.567+0000] {taskinstance.py:1165} INFO - Dependencies all met for <TaskInstance: generic_transfer_operator.load_upload_data manual__2023-09-21T13:37:36.894582+00:00 [queued]>
[2023-09-21T13:37:38.568+0000] {taskinstance.py:1362} INFO - 
--------------------------------------------------------------------------------
[2023-09-21T13:37:38.569+0000] {taskinstance.py:1363} INFO - Starting attempt 1 of 1
[2023-09-21T13:37:38.570+0000] {taskinstance.py:1364} INFO - 
--------------------------------------------------------------------------------
[2023-09-21T13:37:38.590+0000] {taskinstance.py:1383} INFO - Executing <Task(GenericTransfer): load_upload_data> on 2023-09-21 13:37:36.894582+00:00
[2023-09-21T13:37:38.600+0000] {standard_task_runner.py:55} INFO - Started process 8849 to run task
[2023-09-21T13:37:38.604+0000] {standard_task_runner.py:82} INFO - Running: ['***', 'tasks', 'run', 'generic_transfer_operator', 'load_upload_data', 'manual__2023-09-21T13:37:36.894582+00:00', '--job-id', '22', '--raw', '--subdir', 'DAGS_FOLDER/transfer_data.py', '--cfg-path', '/tmp/tmpwqk571m2']
[2023-09-21T13:37:38.605+0000] {standard_task_runner.py:83} INFO - Job 22: Subtask load_upload_data
[2023-09-21T13:37:38.684+0000] {task_command.py:376} INFO - Running <TaskInstance: generic_transfer_operator.load_upload_data manual__2023-09-21T13:37:36.894582+00:00 [running]> on host 411713a30e55
[2023-09-21T13:37:38.783+0000] {taskinstance.py:1592} INFO - Exporting the following env vars:
AIRFLOW_CTX_DAG_OWNER=***
AIRFLOW_CTX_DAG_ID=generic_transfer_operator
AIRFLOW_CTX_TASK_ID=load_upload_data
AIRFLOW_CTX_EXECUTION_DATE=2023-09-21T13:37:36.894582+00:00
AIRFLOW_CTX_TRY_NUMBER=1
AIRFLOW_CTX_DAG_RUN_ID=manual__2023-09-21T13:37:36.894582+00:00
[2023-09-21T13:37:38.799+0000] {base.py:71} INFO - Using connection ID 'pgdatabase' for task execution.
[2023-09-21T13:37:39.055+0000] {base.py:71} INFO - Using connection ID 'postgres' for task execution.
[2023-09-21T13:37:39.230+0000] {generic_transfer.py:76} INFO - Extracting data from pgdatabase
[2023-09-21T13:37:39.231+0000] {generic_transfer.py:77} INFO - Executing: 
 INSERT INTO ***.machine_learning_customerchurn SELECT * FROM postgres.machine_learning_customerchurn;
[2023-09-21T13:37:39.238+0000] {base.py:71} INFO - Using connection ID 'pgdatabase' for task execution.
[2023-09-21T13:37:39.249+0000] {taskinstance.py:1851} ERROR - Task failed with exception
Traceback (most recent call last):
  File "/home/airflow/.local/lib/python3.7/site-packages/airflow/operators/generic_transfer.py", line 85, in execute
    results = get_records(self.sql)
  File "/home/airflow/.local/lib/python3.7/site-packages/airflow/providers/common/sql/hooks/sql.py", line 217, in get_records
    cur.execute(sql)
psycopg2.errors.UndefinedTable: relation "***.machine_learning_customerchurn" does not exist
LINE 1: INSERT INTO ***.machine_learning_customerchurn SELECT * ...
                    ^

[2023-09-21T13:37:39.260+0000] {taskinstance.py:1406} INFO - Marking task as FAILED. dag_id=generic_transfer_operator, task_id=load_upload_data, execution_date=20230921T133736, start_date=20230921T133738, end_date=20230921T133739
[2023-09-21T13:37:39.274+0000] {standard_task_runner.py:105} ERROR - Failed to execute job 22 for task load_upload_data (relation "***.machine_learning_customerchurn" does not exist
LINE 1: INSERT INTO ***.machine_learning_customerchurn SELECT * ...
                    ^
; 8849)
[2023-09-21T13:37:39.301+0000] {local_task_job.py:164} INFO - Task exited with return code 1
[2023-09-21T13:37:39.320+0000] {local_task_job.py:273} INFO - 0 downstream tasks scheduled from follow-on schedule check
